from django.conf import settings
from django.core.exceptions import ValidationError
from django.db import models

from flights.models import Flight


class Order(models.Model):
    created_at = models.DateTimeField(auto_now_add=True)
    user = models.ForeignKey(
        settings.AUTH_USER_MODEL, on_delete=models.CASCADE
    )


class Ticket(models.Model):
    row = models.IntegerField()
    seat = models.IntegerField()
    flight = models.ForeignKey(
        Flight,
        related_name="tickets",
        on_delete=models.CASCADE
    )
    order = models.ForeignKey(
        Order,
        related_name="tickets",
        on_delete=models.CASCADE
    )

    @staticmethod
    def validate_ticket(row, seat, flight, error_to_raise):
        for ticket_attr_value, ticket_attr_name, flight_attr_name in [
            (row, "row", "rows"),
            (seat, "seat", "seats_in_row"),
        ]:
            count_attrs = getattr(flight, flight_attr_name)
            if not (1 <= ticket_attr_value <= count_attrs):
                raise error_to_raise(
                    {
                        ticket_attr_name: f"{ticket_attr_name} "
                        f"number must be in available range: "
                        f"(1, {flight_attr_name}): "
                        f"(1, {count_attrs})"
                    }
                )

    def clean(self):
        Ticket.validate_ticket(
            self.row,
            self.seat,
            self.flight.airplane,
            ValidationError,
        )

    def save(
        self,
        force_insert=False,
        force_update=False,
        using=None,
        update_fields=None,
    ):
        self.full_clean()
        return super(Ticket, self).save(
            force_insert, force_update, using, update_fields
        )
